<?xml version="1.0" encoding="UTF-8"?>

<mujoco model="ur5e_with_mop_and_dust">
   <compiler angle="radian" meshdir="assets" autolimits="true" />
   <option integrator="implicitfast" timestep="0.01" viscosity="0.01" />

   <!-- ================= DEFAULT SETTINGS ================= -->
   <default>
      <default class="ur5e">
         <default class="visual">
            <geom type="mesh" contype="0" conaffinity="0" group="2" />
         </default>
         <default class="collision">
            <geom type="capsule" group="3" />
            <default class="eef_collision">
               <geom type="cylinder" />
            </default>
         </default>
         <joint axis="0 1 0" range="-6.28319 6.28319" />
         <default class="joint_limited">
            <joint range="-3.1415 3.1415" />
         </default>
         <default class="position">
            <position ctrlrange="-6.2831 6.2831" kp="500" kv="25" forcerange="-150 150" />
            <default class="position_limited">
               <position ctrlrange="-3.1415 3.1415" />
            </default>
            <default class="position_small">
               <position kp="500" kv="25" forcerange="-28 28" />
            </default>
         </default>
      </default>
      <!-- Improved dust particle physics for MuJoCo 3.3.5 -->
      <default class="dust">
         <geom type="sphere" size="0.008" density="600" friction="0.8 0.1 0.05" condim="3"
            contype="1" conaffinity="1" group="1"
            solref="0.02 1.0" solimp="0.9 0.95 0.001" />
      </default>
   </default>

   <!-- ================= VISUAL SETTINGS ================= -->


   <!-- ================= MATERIALS + MESHES ================= -->
   <asset>
      <texture name="skybox" type="skybox" builtin="gradient"
         rgb1="0.7 0.85 1" rgb2="0.2 0.3 0.5" width="512" height="512" />
      <texture name="ground_tex" type="2d" builtin="checker" width="512" height="512"
         rgb1="0.2 0.4 0.8" rgb2="0.9 0.9 1" mark="cross" random="0.01" />
      <material name="ground_mat" texture="ground_tex" texrepeat="4 4"
         rgba="1 1 1 1" specular="1" shininess="1" reflectance="0.5" />
      <material name="black" rgba="0.033 0.033 0.033 1" />
      <material name="jointgray" rgba="0.278 0.278 0.278 1" />
      <material name="linkgray" rgba="0.82 0.82 0.82 1" />
      <material name="urblue" rgba="0.49 0.678 0.8 1" />
      <material name="table_material" rgba="0.6 0.4 0.2 1" />
      <material name="dust_material" rgba="1 1 1 1" />
      <!-- Purple material for the mop -->
      <material name="mop_purple" rgba="0.18 0.05 0.35 1" specular="0.5" shininess="0.6" />
      <!-- Dark green material for the mop -->
      <material name="mop_dark_green" rgba="0.05 0.35 0.15 1" specular="0.4" shininess="0.5" />

      <!-- Robot meshes -->
      <mesh file="base_0.obj" />
      <mesh file="base_1.obj" />
      <mesh file="shoulder_0.obj" />
      <mesh file="shoulder_1.obj" />
      <mesh file="shoulder_2.obj" />
      <mesh file="upperarm_0.obj" />
      <mesh file="upperarm_1.obj" />
      <mesh file="upperarm_2.obj" />
      <mesh file="upperarm_3.obj" />
      <mesh file="forearm_0.obj" />
      <mesh file="forearm_1.obj" />
      <mesh file="forearm_2.obj" />
      <mesh file="forearm_3.obj" />
      <mesh file="wrist1_0.obj" />
      <mesh file="wrist1_1.obj" />
      <mesh file="wrist1_2.obj" />
      <mesh file="wrist2_0.obj" />
      <mesh file="wrist2_1.obj" />
      <mesh file="wrist2_2.obj" />
      <mesh file="wrist3.obj" />

      <!-- Table and tool meshes -->
      <mesh file="test.stl" scale="1 1 1" name="table" />
      <mesh name="base_mesh" file="mop_base.obj" scale="0.002 0.002 0.002" />
      <mesh name="handle_mesh" file="mop_handle.obj" scale="0.002 0.002 0.002" />
   </asset>

   <!-- Visual settings: skybox + haze for infinite horizon look -->
   <visual>
      <map znear="0.01" zfar="200" fogstart="8" fogend="60" />
   </visual>

   <!-- ================= WORLD OBJECTS ================= -->

   <!-- ================= WORLD OBJECTS ================= -->
   <worldbody>
      <!-- Key lights -->
      <light name="sun_key" directional="true" pos="0 0 5" dir="0 0 -1"
         diffuse="0.15 0.15 0.15" ambient="0.15 0.15 0.15" specular="0.15 0.15 0.15"
         castshadow="false" />
      <!-- <light name="fill" pos="2 2 3" dir="-1 -1 -1"
           diffuse="0.6 0.6 0.7" ambient="0.2 0.2 0.2" specular="0.1 0.1 0.1" castshadow="false"/> -->
      <!-- Ground with proper contact properties -->
      <geom name="ground" type="plane" size="10 10 0.1" material="ground_mat"
         rgba="0.5 0.5 0.5 1" pos="0 0 0"
         solref="0.02 1.0" solimp="0.9 0.95 0.001" friction="0.9 0.1 0.05" />
      <!-- pos="-1.35 -0.7 -0.01" -->

      <!-- Table positioned as base platform -->
      <body name="table" pos="0 0 0">
         <inertial mass="50" pos="0 0 0.05" diaginertia="10 10 5" />
         <geom name="table_collision" type="box" size="1 0.6 0.45" pos="0.0 0.0 0.01"
            material="table_material" group="3" contype="1" conaffinity="1"
            solref="0.02 1.0" solimp="0.9 0.95 0.001" friction="0.7 0.1 0.05" />
         <geom name="table_visual" type="mesh" mesh="table" material="table_material" class="visual"
            pos="1 0.6 0" />
         <!-- 45-deg wedges along table edges (width ≈ 0.10 m, thickness ≈ 0.02 m) -->
         <!-- Table collision box extents in table frame: x in [-2.7, 0], y in [-1.4, 0], top z ≈
        0.49 -->
         <!-- y = 0 edge (north), tilt toward -y -->
         <!-- <geom name="wedge_y_pos" type="box" size="1.05 0.05 0.01"
        pos="0.0 0.65 0.4552" axisangle="1 0 0 0.1054"
        group="3" contype="1" conaffinity="1" friction="0.8 0.1 0.05" rgba="0.8 0.8 0.8 1" /> -->

         <!-- y = -1.4 edge (south), tilt toward +y -->
         <!-- <geom name="wedge_y_neg" type="box" size="1.05 0.05 0.01"
        pos="0.0 -0.6 0.4552" axisangle="1 0 0 -0.1054"
        group="3" contype="1" conaffinity="1" friction="0.8 0.1 0.05" rgba="0.8 0.8 0.8 1" /> -->

         <!-- x = 0 edge (east), tilt toward -x -->
         <!-- <geom name="wedge_x_pos" type="box" size="0.08 0.65 0.01"
        pos="1 0.0 0.4552" axisangle="0 1 0 -0.1054"
        group="3" contype="1" conaffinity="1" friction="0.8 0.1 0.05" rgba="0.8 0.8 0.8 1" /> -->

         <!-- x = -2.7 edge (west), tilt toward +x -->
         <!-- <geom name="wedge_x_neg" type="box" size="0.08 0.65 0.01"
        pos="-1 0.0 0.4552" axisangle="0 1 0 0.1054"
        group="3" contype="1" conaffinity="1" friction="0.8 0.1 0.05" rgba="0.8 0.8 0.8 1" /> -->
      </body>

      <!-- UR5e Robot mounted ON the table surface -->
      <body name="base" pos="0.0 0.5 0.45" quat="1 0 0 1" childclass="ur5e">
         <inertial mass="4" pos="0 0 0" diaginertia="0.0044 0.0044 0.0072" />
         <geom mesh="base_0" material="black" class="visual" />
         <geom mesh="base_1" material="jointgray" class="visual" />
         <!-- Base collision geometry to sit on table -->
         <geom name="base_collision" type="cylinder" size="0.06 0.02" pos="0 0 -0.01"
            contype="1" conaffinity="1" group="3" friction="0.8 0.1 0.05" />

         <body name="shoulder_link" pos="0 0 0.163">
            <inertial mass="3.7" pos="0 0 0" diaginertia="0.0102 0.0102 0.0066" />
            <joint name="shoulder_pan" axis="0 0 1" />
            <geom mesh="shoulder_0" material="urblue" class="visual" />
            <geom mesh="shoulder_1" material="black" class="visual" />
            <geom mesh="shoulder_2" material="jointgray" class="visual" />

            <body name="upper_arm_link" pos="0 0.138 0" quat="1 0 1 0">
               <inertial mass="8.39" pos="0 0 0.2125" diaginertia="0.133 0.133 0.015" />
               <joint name="shoulder_lift" />
               <geom mesh="upperarm_0" material="linkgray" class="visual" />
               <geom mesh="upperarm_1" material="black" class="visual" />
               <geom mesh="upperarm_2" material="jointgray" class="visual" />
               <geom mesh="upperarm_3" material="urblue" class="visual" />

               <body name="forearm_link" pos="0 -0.131 0.425">
                  <inertial mass="2.27" pos="0 0 0.196" diaginertia="0.031 0.031 0.004" />
                  <joint name="elbow" class="joint_limited" />
                  <geom mesh="forearm_0" material="urblue" class="visual" />
                  <geom mesh="forearm_1" material="linkgray" class="visual" />
                  <geom mesh="forearm_2" material="black" class="visual" />
                  <geom mesh="forearm_3" material="jointgray" class="visual" />

                  <body name="wrist_1_link" pos="0 0 0.392" quat="1 0 1 0">
                     <inertial mass="1.219" pos="0 0.127 0" diaginertia="0.0025 0.0025 0.0021" />
                     <joint name="wrist_1" />
                     <geom mesh="wrist1_0" material="black" class="visual" />
                     <geom mesh="wrist1_1" material="urblue" class="visual" />
                     <geom mesh="wrist1_2" material="jointgray" class="visual" />

                     <body name="wrist_2_link" pos="0 0.127 0">
                        <inertial mass="1.219" pos="0 0 0.1" diaginertia="0.0025 0.0025 0.0021" />
                        <joint name="wrist_2" axis="0 0 1" />
                        <geom mesh="wrist2_0" material="black" class="visual" />
                        <geom mesh="wrist2_1" material="urblue" class="visual" />
                        <geom mesh="wrist2_2" material="jointgray" class="visual" />

                        <body name="wrist_3_link" pos="0 0 0.1">
                           <inertial mass="0.188" pos="0 0.077 0"
                              diaginertia="0.00013 0.0001 0.0001" />
                           <joint name="wrist_3" />
                           <geom mesh="wrist3" material="linkgray" class="visual" />

                           <!-- Mop tool attachment -->
                           <body name="mop_mount" pos="0 0.08 0" quat="1 0 0 1">

                              <body name="mop_tool" pos="0 -0.6 0">
                                 <inertial mass="0.5" pos="0 0 0" diaginertia="0.01 0.01 0.01" />
                                 <geom type="mesh" mesh="handle_mesh" density="500"
                                    friction="0.8 0.1 0.1" />

                                 <body name="mop_head">
                                    <joint name="mop_socket" type="ball" damping="0.5"
                                       limited="false" />
                                    <site name="ee_site" pos="0 -0.02 0.0" size="0.01"
                                       rgba="1 0 0 1" group="4" />
                                    <inertial mass="0.2" pos="0 -0.05 -0.1"
                                       diaginertia="0.005 0.005 0.005" />
                                    <geom type="mesh" mesh="base_mesh" density="500"
                                       friction="0.8 0.1 0.1"
                                       pos="0 -0.05 -0.1" material="mop_dark_green" />
                                 </body>  <!--
                      mop_head -->
                              </body>    <!--
                    mop_tool -->
                           </body>      <!--
                  mop_mount -->
                        </body>        <!--
                wrist_3_link -->
                     </body>          <!--
              wrist_2_link -->
                  </body>            <!--
            wrist_1_link -->
               </body>              <!--
          forearm_link -->
            </body>                <!--
        upper_arm_link -->
         </body>                  <!--
      shoulder_link -->
      </body>                    <!--
    base -->

      <!-- Dust particles properly positioned on table surface around the robot -->
      <!-- Distributed in a cleaning area away from robot base -->
      <!-- Dust balls (stable with solver parameters) -->
      <!--    <body name="dust_1" pos="-1.2340 -0.6502 0.4">-->
      <!--      <freejoint/>-->
      <!--      <inertial mass="0.5" diaginertia="5e-5 5e-5 5e-5" pos="0 0 0"/>-->
      <!--      <geom name="d1" class="dust" material="dust_material"/>-->
      <!--    </body>-->

      <!-- Dust particles - stable until mop pushes them -->


      <body name="ball_1" pos="-0.7055 0.2521 0.48">
         <freejoint />
         <inertial mass="0.03" diaginertia="5.6e-05 5.6e-05 5.6e-05" pos="0 0 0" />
         <geom type="sphere" size="0.02" material="dust_material" />
      </body>
      <body name="ball_2" pos="-0.2825 -0.4197 0.48">
         <freejoint />
         <inertial mass="0.03" diaginertia="5.6e-05 5.6e-05 5.6e-05" pos="0 0 0" />
         <geom type="sphere" size="0.02" material="dust_material" />
      </body>
      <body name="ball_3" pos="0.8755 0.449 0.48">
         <freejoint />
         <inertial mass="0.03" diaginertia="5.6e-05 5.6e-05 5.6e-05" pos="0 0 0" />
         <geom type="sphere" size="0.02" material="dust_material" />
      </body>
      <body name="ball_4" pos="0.5409 0.1351 0.48">
         <freejoint />
         <inertial mass="0.03" diaginertia="5.6e-05 5.6e-05 5.6e-05" pos="0 0 0" />
         <geom type="sphere" size="0.02" material="dust_material" />
      </body>
      <body name="ball_5" pos="-0.9071 -0.15 0.48">
         <freejoint />
         <inertial mass="0.03" diaginertia="5.6e-05 5.6e-05 5.6e-05" pos="0 0 0" />
         <geom type="sphere" size="0.02" material="dust_material" />
      </body>
      <body name="ball_6" pos="-0.4169 0.2821 0.48">
         <freejoint />
         <inertial mass="0.03" diaginertia="5.6e-05 5.6e-05 5.6e-05" pos="0 0 0" />
         <geom type="sphere" size="0.02" material="dust_material" />
      </body>
      <body name="ball_7" pos="-0.5863 -0.1627 0.48">
         <freejoint />
         <inertial mass="0.03" diaginertia="5.6e-05 5.6e-05 5.6e-05" pos="0 0 0" />
         <geom type="sphere" size="0.02" material="dust_material" />
      </body>
      <body name="ball_8" pos="-0.9204 -0.2712 0.48">
         <freejoint />
         <inertial mass="0.03" diaginertia="5.6e-05 5.6e-05 5.6e-05" pos="0 0 0" />
         <geom type="sphere" size="0.02" material="dust_material" />
      </body>
      <body name="ball_9" pos="0.4209 -0.0038 0.48">
         <freejoint />
         <inertial mass="0.03" diaginertia="5.6e-05 5.6e-05 5.6e-05" pos="0 0 0" />
         <geom type="sphere" size="0.02" material="dust_material" />
      </body>
      <body name="ball_10" pos="0.6338 -0.472 0.48">
         <freejoint />
         <inertial mass="0.03" diaginertia="5.6e-05 5.6e-05 5.6e-05" pos="0 0 0" />
         <geom type="sphere" size="0.02" material="dust_material" />
      </body>
      <body name="ball_11" pos="0.6979 0.1153 0.48">
         <freejoint />
         <inertial mass="0.03" diaginertia="5.6e-05 5.6e-05 5.6e-05" pos="0 0 0" />
         <geom type="sphere" size="0.02" material="dust_material" />
      </body>
      <body name="ball_12" pos="-0.3395 -0.1815 0.48">
         <freejoint />
         <inertial mass="0.03" diaginertia="5.6e-05 5.6e-05 5.6e-05" pos="0 0 0" />
         <geom type="sphere" size="0.02" material="dust_material" />
      </body>
      <body name="ball_13" pos="0.9053 0.4146 0.48">
         <freejoint />
         <inertial mass="0.03" diaginertia="5.6e-05 5.6e-05 5.6e-05" pos="0 0 0" />
         <geom type="sphere" size="0.02" material="dust_material" />
      </body>
      <body name="ball_14" pos="-0.8305 0.1788 0.48">
         <freejoint />
         <inertial mass="0.03" diaginertia="5.6e-05 5.6e-05 5.6e-05" pos="0 0 0" />
         <geom type="sphere" size="0.02" material="dust_material" />
      </body>
      <body name="ball_15" pos="-0.4667 -0.4841 0.48">
         <freejoint />
         <inertial mass="0.03" diaginertia="5.6e-05 5.6e-05 5.6e-05" pos="0 0 0" />
         <geom type="sphere" size="0.02" material="dust_material" />
      </body>
      <body name="ball_16" pos="0.0982 -0.2803 0.48">
         <freejoint />
         <inertial mass="0.03" diaginertia="5.6e-05 5.6e-05 5.6e-05" pos="0 0 0" />
         <geom type="sphere" size="0.02" material="dust_material" />
      </body>
      <body name="ball_17" pos="-0.5261 0.0172 0.48">
         <freejoint />
         <inertial mass="0.03" diaginertia="5.6e-05 5.6e-05 5.6e-05" pos="0 0 0" />
         <geom type="sphere" size="0.02" material="dust_material" />
      </body>
      <body name="ball_18" pos="-0.7881 -0.3586 0.48">
         <freejoint />
         <inertial mass="0.03" diaginertia="5.6e-05 5.6e-05 5.6e-05" pos="0 0 0" />
         <geom type="sphere" size="0.02" material="dust_material" />
      </body>
      <body name="ball_19" pos="0.7686 0.0999 0.48">
         <freejoint />
         <inertial mass="0.03" diaginertia="5.6e-05 5.6e-05 5.6e-05" pos="0 0 0" />
         <geom type="sphere" size="0.02" material="dust_material" />
      </body>
      <body name="ball_20" pos="-0.6161 -0.2906 0.48">
         <freejoint />
         <inertial mass="0.03" diaginertia="5.6e-05 5.6e-05 5.6e-05" pos="0 0 0" />
         <geom type="sphere" size="0.02" material="dust_material" />
      </body>
      <body name="ball_21" pos="0.6023 0.3194 0.48">
         <freejoint />
         <inertial mass="0.03" diaginertia="5.6e-05 5.6e-05 5.6e-05" pos="0 0 0" />
         <geom type="sphere" size="0.02" material="dust_material" />
      </body>
      <body name="ball_22" pos="-0.2883 -0.0435 0.48">
         <freejoint />
         <inertial mass="0.03" diaginertia="5.6e-05 5.6e-05 5.6e-05" pos="0 0 0" />
         <geom type="sphere" size="0.02" material="dust_material" />
      </body>
      <body name="ball_23" pos="-0.9563 0.202 0.48">
         <freejoint />
         <inertial mass="0.03" diaginertia="5.6e-05 5.6e-05 5.6e-05" pos="0 0 0" />
         <geom type="sphere" size="0.02" material="dust_material" />
      </body>
      <body name="ball_24" pos="0.1139 -0.4511 0.48">
         <freejoint />
         <inertial mass="0.03" diaginertia="5.6e-05 5.6e-05 5.6e-05" pos="0 0 0" />
         <geom type="sphere" size="0.02" material="dust_material" />
      </body>
      <body name="ball_25" pos="-0.7779 -0.0802 0.48">
         <freejoint />
         <inertial mass="0.03" diaginertia="5.6e-05 5.6e-05 5.6e-05" pos="0 0 0" />
         <geom type="sphere" size="0.02" material="dust_material" />
      </body>
      <body name="ball_26" pos="-0.7151 -0.4572 0.48">
         <freejoint />
         <inertial mass="0.03" diaginertia="5.6e-05 5.6e-05 5.6e-05" pos="0 0 0" />
         <geom type="sphere" size="0.02" material="dust_material" />
      </body>
      <body name="ball_27" pos="-0.5177 0.441 0.48">
         <freejoint />
         <inertial mass="0.03" diaginertia="5.6e-05 5.6e-05 5.6e-05" pos="0 0 0" />
         <geom type="sphere" size="0.02" material="dust_material" />
      </body>
      <body name="ball_28" pos="0.9589 -0.4213 0.48">
         <freejoint />
         <inertial mass="0.03" diaginertia="5.6e-05 5.6e-05 5.6e-05" pos="0 0 0" />
         <geom type="sphere" size="0.02" material="dust_material" />
      </body>
      <body name="ball_29" pos="-0.2456 -0.2487 0.48">
         <freejoint />
         <inertial mass="0.03" diaginertia="5.6e-05 5.6e-05 5.6e-05" pos="0 0 0" />
         <geom type="sphere" size="0.02" material="dust_material" />
      </body>
      <body name="ball_30" pos="-0.2432 0.2011 0.48">
         <freejoint />
         <inertial mass="0.03" diaginertia="5.6e-05 5.6e-05 5.6e-05" pos="0 0 0" />
         <geom type="sphere" size="0.02" material="dust_material" />
      </body>
      <body name="ball_31" pos="-0.5087 0.2843 0.48">
         <freejoint />
         <inertial mass="0.03" diaginertia="5.6e-05 5.6e-05 5.6e-05" pos="0 0 0" />
         <geom type="sphere" size="0.02" material="dust_material" />
      </body>
      <body name="ball_32" pos="-0.8085 0.3448 0.48">
         <freejoint />
         <inertial mass="0.03" diaginertia="5.6e-05 5.6e-05 5.6e-05" pos="0 0 0" />
         <geom type="sphere" size="0.02" material="dust_material" />
      </body>
      <body name="ball_33" pos="-0.9528 -0.1633 0.48">
         <freejoint />
         <inertial mass="0.03" diaginertia="5.6e-05 5.6e-05 5.6e-05" pos="0 0 0" />
         <geom type="sphere" size="0.02" material="dust_material" />
      </body>
      <body name="ball_34" pos="-0.2631 0.2173 0.48">
         <freejoint />
         <inertial mass="0.03" diaginertia="5.6e-05 5.6e-05 5.6e-05" pos="0 0 0" />
         <geom type="sphere" size="0.02" material="dust_material" />
      </body>
      <body name="ball_35" pos="0.2864 0.2762 0.48">
         <freejoint />
         <inertial mass="0.03" diaginertia="5.6e-05 5.6e-05 5.6e-05" pos="0 0 0" />
         <geom type="sphere" size="0.02" material="dust_material" />
      </body>
      <body name="ball_36" pos="-0.4114 -0.3183 0.48">
         <freejoint />
         <inertial mass="0.03" diaginertia="5.6e-05 5.6e-05 5.6e-05" pos="0 0 0" />
         <geom type="sphere" size="0.02" material="dust_material" />
      </body>
      <body name="ball_37" pos="-0.3106 -0.1709 0.48">
         <freejoint />
         <inertial mass="0.03" diaginertia="5.6e-05 5.6e-05 5.6e-05" pos="0 0 0" />
         <geom type="sphere" size="0.02" material="dust_material" />
      </body>
      <body name="ball_38" pos="-0.2698 -0.1953 0.48">
         <freejoint />
         <inertial mass="0.03" diaginertia="5.6e-05 5.6e-05 5.6e-05" pos="0 0 0" />
         <geom type="sphere" size="0.02" material="dust_material" />
      </body>
      <body name="ball_39" pos="0.1902 0.3199 0.48">
         <freejoint />
         <inertial mass="0.03" diaginertia="5.6e-05 5.6e-05 5.6e-05" pos="0 0 0" />
         <geom type="sphere" size="0.02" material="dust_material" />
      </body>
      <body name="ball_40" pos="-0.8037 -0.0559 0.48">
         <freejoint />
         <inertial mass="0.03" diaginertia="5.6e-05 5.6e-05 5.6e-05" pos="0 0 0" />
         <geom type="sphere" size="0.02" material="dust_material" />
      </body>
      <body name="ball_41" pos="0.9257 0.2061 0.48">
         <freejoint />
         <inertial mass="0.03" diaginertia="5.6e-05 5.6e-05 5.6e-05" pos="0 0 0" />
         <geom type="sphere" size="0.02" material="dust_material" />
      </body>
      <body name="ball_42" pos="-0.2063 0.1425 0.48">
         <freejoint />
         <inertial mass="0.03" diaginertia="5.6e-05 5.6e-05 5.6e-05" pos="0 0 0" />
         <geom type="sphere" size="0.02" material="dust_material" />
      </body>
      <body name="ball_43" pos="0.1886 0.1804 0.48">
         <freejoint />
         <inertial mass="0.03" diaginertia="5.6e-05 5.6e-05 5.6e-05" pos="0 0 0" />
         <geom type="sphere" size="0.02" material="dust_material" />
      </body>
      <body name="ball_44" pos="-0.5565 0.0491 0.48">
         <freejoint />
         <inertial mass="0.03" diaginertia="5.6e-05 5.6e-05 5.6e-05" pos="0 0 0" />
         <geom type="sphere" size="0.02" material="dust_material" />
      </body>
      <body name="ball_45" pos="0.1359 0.2984 0.48">
         <freejoint />
         <inertial mass="0.03" diaginertia="5.6e-05 5.6e-05 5.6e-05" pos="0 0 0" />
         <geom type="sphere" size="0.02" material="dust_material" />
      </body>
      <body name="ball_46" pos="0.2434 -0.177 0.48">
         <freejoint />
         <inertial mass="0.03" diaginertia="5.6e-05 5.6e-05 5.6e-05" pos="0 0 0" />
         <geom type="sphere" size="0.02" material="dust_material" />
      </body>
      <body name="ball_47" pos="-0.5253 -0.3758 0.48">
         <freejoint />
         <inertial mass="0.03" diaginertia="5.6e-05 5.6e-05 5.6e-05" pos="0 0 0" />
         <geom type="sphere" size="0.02" material="dust_material" />
      </body>
      <body name="ball_48" pos="0.6187 -0.4603 0.48">
         <freejoint />
         <inertial mass="0.03" diaginertia="5.6e-05 5.6e-05 5.6e-05" pos="0 0 0" />
         <geom type="sphere" size="0.02" material="dust_material" />
      </body>
      <body name="ball_49" pos="-0.7864 0.0294 0.48">
         <freejoint />
         <inertial mass="0.03" diaginertia="5.6e-05 5.6e-05 5.6e-05" pos="0 0 0" />
         <geom type="sphere" size="0.02" material="dust_material" />
      </body>
      <body name="ball_50" pos="-0.9419 0.1613 0.48">
         <freejoint />
         <inertial mass="0.03" diaginertia="5.6e-05 5.6e-05 5.6e-05" pos="0 0 0" />
         <geom type="sphere" size="0.02" material="dust_material" />
      </body>
      <body name="ball_51" pos="-0.2207 0.3592 0.48">
         <freejoint />
         <inertial mass="0.03" diaginertia="5.6e-05 5.6e-05 5.6e-05" pos="0 0 0" />
         <geom type="sphere" size="0.02" material="dust_material" />
      </body>
      <body name="ball_52" pos="-0.1004 0.4171 0.48">
         <freejoint />
         <inertial mass="0.03" diaginertia="5.6e-05 5.6e-05 5.6e-05" pos="0 0 0" />
         <geom type="sphere" size="0.02" material="dust_material" />
      </body>
      <body name="ball_53" pos="0.4885 -0.3645 0.48">
         <freejoint />
         <inertial mass="0.03" diaginertia="5.6e-05 5.6e-05 5.6e-05" pos="0 0 0" />
         <geom type="sphere" size="0.02" material="dust_material" />
      </body>
      <body name="ball_54" pos="0.9249 0.488 0.48">
         <freejoint />
         <inertial mass="0.03" diaginertia="5.6e-05 5.6e-05 5.6e-05" pos="0 0 0" />
         <geom type="sphere" size="0.02" material="dust_material" />
      </body>
      <body name="ball_55" pos="0.4788 -0.3271 0.48">
         <freejoint />
         <inertial mass="0.03" diaginertia="5.6e-05 5.6e-05 5.6e-05" pos="0 0 0" />
         <geom type="sphere" size="0.02" material="dust_material" />
      </body>
      <body name="ball_56" pos="0.0852 -0.4393 0.48">
         <freejoint />
         <inertial mass="0.03" diaginertia="5.6e-05 5.6e-05 5.6e-05" pos="0 0 0" />
         <geom type="sphere" size="0.02" material="dust_material" />
      </body>
      <body name="ball_57" pos="0.772 0.3185 0.48">
         <freejoint />
         <inertial mass="0.03" diaginertia="5.6e-05 5.6e-05 5.6e-05" pos="0 0 0" />
         <geom type="sphere" size="0.02" material="dust_material" />
      </body>
      <body name="ball_58" pos="0.4912 0.0803 0.48">
         <freejoint />
         <inertial mass="0.03" diaginertia="5.6e-05 5.6e-05 5.6e-05" pos="0 0 0" />
         <geom type="sphere" size="0.02" material="dust_material" />
      </body>
      <body name="ball_59" pos="0.9375 0.4415 0.48">
         <freejoint />
         <inertial mass="0.03" diaginertia="5.6e-05 5.6e-05 5.6e-05" pos="0 0 0" />
         <geom type="sphere" size="0.02" material="dust_material" />
      </body>
      <body name="ball_60" pos="0.2373 -0.0261 0.48">
         <freejoint />
         <inertial mass="0.03" diaginertia="5.6e-05 5.6e-05 5.6e-05" pos="0 0 0" />
         <geom type="sphere" size="0.02" material="dust_material" />
      </body>
      <body name="ball_61" pos="0.4966 -0.4322 0.48">
         <freejoint />
         <inertial mass="0.03" diaginertia="5.6e-05 5.6e-05 5.6e-05" pos="0 0 0" />
         <geom type="sphere" size="0.02" material="dust_material" />
      </body>
      <body name="ball_62" pos="-0.1515 -0.0764 0.48">
         <freejoint />
         <inertial mass="0.03" diaginertia="5.6e-05 5.6e-05 5.6e-05" pos="0 0 0" />
         <geom type="sphere" size="0.02" material="dust_material" />
      </body>
      <body name="ball_63" pos="-0.3846 -0.1189 0.48">
         <freejoint />
         <inertial mass="0.03" diaginertia="5.6e-05 5.6e-05 5.6e-05" pos="0 0 0" />
         <geom type="sphere" size="0.02" material="dust_material" />
      </body>
      <body name="ball_64" pos="-0.2432 -0.3427 0.48">
         <freejoint />
         <inertial mass="0.03" diaginertia="5.6e-05 5.6e-05 5.6e-05" pos="0 0 0" />
         <geom type="sphere" size="0.02" material="dust_material" />
      </body>
      <body name="ball_65" pos="0.8055 -0.4466 0.48">
         <freejoint />
         <inertial mass="0.03" diaginertia="5.6e-05 5.6e-05 5.6e-05" pos="0 0 0" />
         <geom type="sphere" size="0.02" material="dust_material" />
      </body>
      <body name="ball_66" pos="0.4144 -0.1835 0.48">
         <freejoint />
         <inertial mass="0.03" diaginertia="5.6e-05 5.6e-05 5.6e-05" pos="0 0 0" />
         <geom type="sphere" size="0.02" material="dust_material" />
      </body>
      <body name="ball_67" pos="0.1533 -0.0613 0.48">
         <freejoint />
         <inertial mass="0.03" diaginertia="5.6e-05 5.6e-05 5.6e-05" pos="0 0 0" />
         <geom type="sphere" size="0.02" material="dust_material" />
      </body>
      <body name="ball_68" pos="0.8609 -0.4262 0.48">
         <freejoint />
         <inertial mass="0.03" diaginertia="5.6e-05 5.6e-05 5.6e-05" pos="0 0 0" />
         <geom type="sphere" size="0.02" material="dust_material" />
      </body>
      <body name="ball_69" pos="0.4392 -0.3346 0.48">
         <freejoint />
         <inertial mass="0.03" diaginertia="5.6e-05 5.6e-05 5.6e-05" pos="0 0 0" />
         <geom type="sphere" size="0.02" material="dust_material" />
      </body>
      <body name="ball_70" pos="-0.1725 -0.4867 0.48">
         <freejoint />
         <inertial mass="0.03" diaginertia="5.6e-05 5.6e-05 5.6e-05" pos="0 0 0" />
         <geom type="sphere" size="0.02" material="dust_material" />
      </body>
      <body name="ball_71" pos="0.4406 0.2701 0.48">
         <freejoint />
         <inertial mass="0.03" diaginertia="5.6e-05 5.6e-05 5.6e-05" pos="0 0 0" />
         <geom type="sphere" size="0.02" material="dust_material" />
      </body>
      <body name="ball_72" pos="0.7292 0.0015 0.48">
         <freejoint />
         <inertial mass="0.03" diaginertia="5.6e-05 5.6e-05 5.6e-05" pos="0 0 0" />
         <geom type="sphere" size="0.02" material="dust_material" />
      </body>
      <body name="ball_73" pos="0.4669 -0.2445 0.48">
         <freejoint />
         <inertial mass="0.03" diaginertia="5.6e-05 5.6e-05 5.6e-05" pos="0 0 0" />
         <geom type="sphere" size="0.02" material="dust_material" />
      </body>
      <body name="ball_74" pos="0.1521 -0.3451 0.48">
         <freejoint />
         <inertial mass="0.03" diaginertia="5.6e-05 5.6e-05 5.6e-05" pos="0 0 0" />
         <geom type="sphere" size="0.02" material="dust_material" />
      </body>
      <body name="ball_75" pos="-0.3721 0.2836 0.48">
         <freejoint />
         <inertial mass="0.03" diaginertia="5.6e-05 5.6e-05 5.6e-05" pos="0 0 0" />
         <geom type="sphere" size="0.02" material="dust_material" />
      </body>
      <body name="ball_76" pos="0.0378 0.3802 0.48">
         <freejoint />
         <inertial mass="0.03" diaginertia="5.6e-05 5.6e-05 5.6e-05" pos="0 0 0" />
         <geom type="sphere" size="0.02" material="dust_material" />
      </body>
      <body name="ball_77" pos="0.1 0.0962 0.48">
         <freejoint />
         <inertial mass="0.03" diaginertia="5.6e-05 5.6e-05 5.6e-05" pos="0 0 0" />
         <geom type="sphere" size="0.02" material="dust_material" />
      </body>
      <body name="ball_78" pos="0.2769 -0.4433 0.48">
         <freejoint />
         <inertial mass="0.03" diaginertia="5.6e-05 5.6e-05 5.6e-05" pos="0 0 0" />
         <geom type="sphere" size="0.02" material="dust_material" />
      </body>
      <body name="ball_79" pos="-0.811 -0.0632 0.48">
         <freejoint />
         <inertial mass="0.03" diaginertia="5.6e-05 5.6e-05 5.6e-05" pos="0 0 0" />
         <geom type="sphere" size="0.02" material="dust_material" />
      </body>
      <body name="ball_80" pos="0.6315 0.0557 0.48">
         <freejoint />
         <inertial mass="0.03" diaginertia="5.6e-05 5.6e-05 5.6e-05" pos="0 0 0" />
         <geom type="sphere" size="0.02" material="dust_material" />
      </body>
      <body name="ball_81" pos="-0.58 -0.2938 0.48">
         <freejoint />
         <inertial mass="0.03" diaginertia="5.6e-05 5.6e-05 5.6e-05" pos="0 0 0" />
         <geom type="sphere" size="0.02" material="dust_material" />
      </body>
      <body name="ball_82" pos="-0.9812 0.3669 0.48">
         <freejoint />
         <inertial mass="0.03" diaginertia="5.6e-05 5.6e-05 5.6e-05" pos="0 0 0" />
         <geom type="sphere" size="0.02" material="dust_material" />
      </body>
      <body name="ball_83" pos="-0.3381 -0.0447 0.48">
         <freejoint />
         <inertial mass="0.03" diaginertia="5.6e-05 5.6e-05 5.6e-05" pos="0 0 0" />
         <geom type="sphere" size="0.02" material="dust_material" />
      </body>
      <body name="ball_84" pos="-0.5873 0.0053 0.48">
         <freejoint />
         <inertial mass="0.03" diaginertia="5.6e-05 5.6e-05 5.6e-05" pos="0 0 0" />
         <geom type="sphere" size="0.02" material="dust_material" />
      </body>
      <body name="ball_85" pos="-0.7521 0.0587 0.48">
         <freejoint />
         <inertial mass="0.03" diaginertia="5.6e-05 5.6e-05 5.6e-05" pos="0 0 0" />
         <geom type="sphere" size="0.02" material="dust_material" />
      </body>
      <body name="ball_86" pos="0.8929 -0.3191 0.48">
         <freejoint />
         <inertial mass="0.03" diaginertia="5.6e-05 5.6e-05 5.6e-05" pos="0 0 0" />
         <geom type="sphere" size="0.02" material="dust_material" />
      </body>
      <body name="ball_87" pos="0.7519 -0.486 0.48">
         <freejoint />
         <inertial mass="0.03" diaginertia="5.6e-05 5.6e-05 5.6e-05" pos="0 0 0" />
         <geom type="sphere" size="0.02" material="dust_material" />
      </body>
      <body name="ball_88" pos="0.7134 -0.0203 0.48">
         <freejoint />
         <inertial mass="0.03" diaginertia="5.6e-05 5.6e-05 5.6e-05" pos="0 0 0" />
         <geom type="sphere" size="0.02" material="dust_material" />
      </body>
      <body name="ball_89" pos="-0.2525 -0.0311 0.48">
         <freejoint />
         <inertial mass="0.03" diaginertia="5.6e-05 5.6e-05 5.6e-05" pos="0 0 0" />
         <geom type="sphere" size="0.02" material="dust_material" />
      </body>
      <body name="ball_90" pos="-0.4441 0.4149 0.48">
         <freejoint />
         <inertial mass="0.03" diaginertia="5.6e-05 5.6e-05 5.6e-05" pos="0 0 0" />
         <geom type="sphere" size="0.02" material="dust_material" />
      </body>
      <body name="ball_91" pos="-0.1508 -0.2992 0.48">
         <freejoint />
         <inertial mass="0.03" diaginertia="5.6e-05 5.6e-05 5.6e-05" pos="0 0 0" />
         <geom type="sphere" size="0.02" material="dust_material" />
      </body>
      <body name="ball_92" pos="0.901 -0.1098 0.48">
         <freejoint />
         <inertial mass="0.03" diaginertia="5.6e-05 5.6e-05 5.6e-05" pos="0 0 0" />
         <geom type="sphere" size="0.02" material="dust_material" />
      </body>
      <body name="ball_93" pos="-0.3103 -0.3641 0.48">
         <freejoint />
         <inertial mass="0.03" diaginertia="5.6e-05 5.6e-05 5.6e-05" pos="0 0 0" />
         <geom type="sphere" size="0.02" material="dust_material" />
      </body>
      <body name="ball_94" pos="-0.0332 -0.4729 0.48">
         <freejoint />
         <inertial mass="0.03" diaginertia="5.6e-05 5.6e-05 5.6e-05" pos="0 0 0" />
         <geom type="sphere" size="0.02" material="dust_material" />
      </body>
      <body name="ball_95" pos="-0.168 0.0195 0.48">
         <freejoint />
         <inertial mass="0.03" diaginertia="5.6e-05 5.6e-05 5.6e-05" pos="0 0 0" />
         <geom type="sphere" size="0.02" material="dust_material" />
      </body>
      <body name="ball_96" pos="-0.0442 0.3805 0.48">
         <freejoint />
         <inertial mass="0.03" diaginertia="5.6e-05 5.6e-05 5.6e-05" pos="0 0 0" />
         <geom type="sphere" size="0.02" material="dust_material" />
      </body>
      <body name="ball_97" pos="-0.3937 0.1733 0.48">
         <freejoint />
         <inertial mass="0.03" diaginertia="5.6e-05 5.6e-05 5.6e-05" pos="0 0 0" />
         <geom type="sphere" size="0.02" material="dust_material" />
      </body>
      <body name="ball_98" pos="-0.5542 -0.4488 0.48">
         <freejoint />
         <inertial mass="0.03" diaginertia="5.6e-05 5.6e-05 5.6e-05" pos="0 0 0" />
         <geom type="sphere" size="0.02" material="dust_material" />
      </body>
      <body name="ball_99" pos="0.6814 -0.2201 0.48">
         <freejoint />
         <inertial mass="0.03" diaginertia="5.6e-05 5.6e-05 5.6e-05" pos="0 0 0" />
         <geom type="sphere" size="0.02" material="dust_material" />
      </body>
      <body name="ball_100" pos="-0.4577 0.4493 0.48">
         <freejoint />
         <inertial mass="0.03" diaginertia="5.6e-05 5.6e-05 5.6e-05" pos="0 0 0" />
         <geom type="sphere" size="0.02" material="dust_material" />
      </body>
      <body name="ball_101" pos="0.629 -0.254 0.48">
         <freejoint />
         <inertial mass="0.03" diaginertia="5.6e-05 5.6e-05 5.6e-05" pos="0 0 0" />
         <geom type="sphere" size="0.02" material="dust_material" />
      </body>
      <body name="ball_102" pos="0.5519 -0.2523 0.48">
         <freejoint />
         <inertial mass="0.03" diaginertia="5.6e-05 5.6e-05 5.6e-05" pos="0 0 0" />
         <geom type="sphere" size="0.02" material="dust_material" />
      </body>
      <body name="ball_103" pos="0.3041 0.0396 0.48">
         <freejoint />
         <inertial mass="0.03" diaginertia="5.6e-05 5.6e-05 5.6e-05" pos="0 0 0" />
         <geom type="sphere" size="0.02" material="dust_material" />
      </body>
      <body name="ball_104" pos="0.1402 0.2656 0.48">
         <freejoint />
         <inertial mass="0.03" diaginertia="5.6e-05 5.6e-05 5.6e-05" pos="0 0 0" />
         <geom type="sphere" size="0.02" material="dust_material" />
      </body>
      <body name="ball_105" pos="0.3986 -0.2738 0.48">
         <freejoint />
         <inertial mass="0.03" diaginertia="5.6e-05 5.6e-05 5.6e-05" pos="0 0 0" />
         <geom type="sphere" size="0.02" material="dust_material" />
      </body>
      <body name="ball_106" pos="-0.2857 -0.0072 0.48">
         <freejoint />
         <inertial mass="0.03" diaginertia="5.6e-05 5.6e-05 5.6e-05" pos="0 0 0" />
         <geom type="sphere" size="0.02" material="dust_material" />
      </body>
      <body name="ball_107" pos="0.9698 -0.0258 0.48">
         <freejoint />
         <inertial mass="0.03" diaginertia="5.6e-05 5.6e-05 5.6e-05" pos="0 0 0" />
         <geom type="sphere" size="0.02" material="dust_material" />
      </body>
      <body name="ball_108" pos="0.1589 0.3736 0.48">
         <freejoint />
         <inertial mass="0.03" diaginertia="5.6e-05 5.6e-05 5.6e-05" pos="0 0 0" />
         <geom type="sphere" size="0.02" material="dust_material" />
      </body>
      <body name="ball_109" pos="-0.5735 -0.1452 0.48">
         <freejoint />
         <inertial mass="0.03" diaginertia="5.6e-05 5.6e-05 5.6e-05" pos="0 0 0" />
         <geom type="sphere" size="0.02" material="dust_material" />
      </body>
      <body name="ball_110" pos="0.4481 0.1424 0.48">
         <freejoint />
         <inertial mass="0.03" diaginertia="5.6e-05 5.6e-05 5.6e-05" pos="0 0 0" />
         <geom type="sphere" size="0.02" material="dust_material" />
      </body>
      <body name="ball_111" pos="0.2533 0.269 0.48">
         <freejoint />
         <inertial mass="0.03" diaginertia="5.6e-05 5.6e-05 5.6e-05" pos="0 0 0" />
         <geom type="sphere" size="0.02" material="dust_material" />
      </body>
      <body name="ball_112" pos="0.4222 0.2459 0.48">
         <freejoint />
         <inertial mass="0.03" diaginertia="5.6e-05 5.6e-05 5.6e-05" pos="0 0 0" />
         <geom type="sphere" size="0.02" material="dust_material" />
      </body>
      <body name="ball_113" pos="-0.2754 -0.2216 0.48">
         <freejoint />
         <inertial mass="0.03" diaginertia="5.6e-05 5.6e-05 5.6e-05" pos="0 0 0" />
         <geom type="sphere" size="0.02" material="dust_material" />
      </body>
      <body name="ball_114" pos="-0.5155 -0.104 0.48">
         <freejoint />
         <inertial mass="0.03" diaginertia="5.6e-05 5.6e-05 5.6e-05" pos="0 0 0" />
         <geom type="sphere" size="0.02" material="dust_material" />
      </body>
      <body name="ball_115" pos="-0.46 0.0427 0.48">
         <freejoint />
         <inertial mass="0.03" diaginertia="5.6e-05 5.6e-05 5.6e-05" pos="0 0 0" />
         <geom type="sphere" size="0.02" material="dust_material" />
      </body>
      <body name="ball_116" pos="-0.7423 0.2018 0.48">
         <freejoint />
         <inertial mass="0.03" diaginertia="5.6e-05 5.6e-05 5.6e-05" pos="0 0 0" />
         <geom type="sphere" size="0.02" material="dust_material" />
      </body>
      <body name="ball_117" pos="0.9379 0.4991 0.48">
         <freejoint />
         <inertial mass="0.03" diaginertia="5.6e-05 5.6e-05 5.6e-05" pos="0 0 0" />
         <geom type="sphere" size="0.02" material="dust_material" />
      </body>
      <body name="ball_118" pos="0.2579 0.0925 0.48">
         <freejoint />
         <inertial mass="0.03" diaginertia="5.6e-05 5.6e-05 5.6e-05" pos="0 0 0" />
         <geom type="sphere" size="0.02" material="dust_material" />
      </body>
      <body name="ball_119" pos="-0.7891 0.3354 0.48">
         <freejoint />
         <inertial mass="0.03" diaginertia="5.6e-05 5.6e-05 5.6e-05" pos="0 0 0" />
         <geom type="sphere" size="0.02" material="dust_material" />
      </body>
      <body name="ball_120" pos="0.1532 0.4227 0.48">
         <freejoint />
         <inertial mass="0.03" diaginertia="5.6e-05 5.6e-05 5.6e-05" pos="0 0 0" />
         <geom type="sphere" size="0.02" material="dust_material" />
      </body>
      <body name="ball_121" pos="-0.3852 -0.1431 0.48">
         <freejoint />
         <inertial mass="0.03" diaginertia="5.6e-05 5.6e-05 5.6e-05" pos="0 0 0" />
         <geom type="sphere" size="0.02" material="dust_material" />
      </body>
      <body name="ball_122" pos="0.8583 0.0993 0.48">
         <freejoint />
         <inertial mass="0.03" diaginertia="5.6e-05 5.6e-05 5.6e-05" pos="0 0 0" />
         <geom type="sphere" size="0.02" material="dust_material" />
      </body>
      <body name="ball_123" pos="0.9964 -0.2542 0.48">
         <freejoint />
         <inertial mass="0.03" diaginertia="5.6e-05 5.6e-05 5.6e-05" pos="0 0 0" />
         <geom type="sphere" size="0.02" material="dust_material" />
      </body>
      <body name="ball_124" pos="0.4512 0.0604 0.48">
         <freejoint />
         <inertial mass="0.03" diaginertia="5.6e-05 5.6e-05 5.6e-05" pos="0 0 0" />
         <geom type="sphere" size="0.02" material="dust_material" />
      </body>
      <body name="ball_125" pos="0.9644 0.2482 0.48">
         <freejoint />
         <inertial mass="0.03" diaginertia="5.6e-05 5.6e-05 5.6e-05" pos="0 0 0" />
         <geom type="sphere" size="0.02" material="dust_material" />
      </body>
      <body name="ball_126" pos="0.2646 -0.0234 0.48">
         <freejoint />
         <inertial mass="0.03" diaginertia="5.6e-05 5.6e-05 5.6e-05" pos="0 0 0" />
         <geom type="sphere" size="0.02" material="dust_material" />
      </body>
      <body name="ball_127" pos="0.1076 0.3597 0.48">
         <freejoint />
         <inertial mass="0.03" diaginertia="5.6e-05 5.6e-05 5.6e-05" pos="0 0 0" />
         <geom type="sphere" size="0.02" material="dust_material" />
      </body>
      <body name="ball_128" pos="0.6891 -0.1667 0.48">
         <freejoint />
         <inertial mass="0.03" diaginertia="5.6e-05 5.6e-05 5.6e-05" pos="0 0 0" />
         <geom type="sphere" size="0.02" material="dust_material" />
      </body>
      <body name="ball_129" pos="0.9235 -0.2099 0.48">
         <freejoint />
         <inertial mass="0.03" diaginertia="5.6e-05 5.6e-05 5.6e-05" pos="0 0 0" />
         <geom type="sphere" size="0.02" material="dust_material" />
      </body>
      <body name="ball_130" pos="0.1639 -0.1019 0.48">
         <freejoint />
         <inertial mass="0.03" diaginertia="5.6e-05 5.6e-05 5.6e-05" pos="0 0 0" />
         <geom type="sphere" size="0.02" material="dust_material" />
      </body>
      <body name="ball_131" pos="0.9907 0.198 0.48">
         <freejoint />
         <inertial mass="0.03" diaginertia="5.6e-05 5.6e-05 5.6e-05" pos="0 0 0" />
         <geom type="sphere" size="0.02" material="dust_material" />
      </body>
      <body name="ball_132" pos="0.6778 0.1505 0.48">
         <freejoint />
         <inertial mass="0.03" diaginertia="5.6e-05 5.6e-05 5.6e-05" pos="0 0 0" />
         <geom type="sphere" size="0.02" material="dust_material" />
      </body>
      <body name="ball_133" pos="-0.7969 -0.3255 0.48">
         <freejoint />
         <inertial mass="0.03" diaginertia="5.6e-05 5.6e-05 5.6e-05" pos="0 0 0" />
         <geom type="sphere" size="0.02" material="dust_material" />
      </body>
      <body name="ball_134" pos="0.332 -0.3359 0.48">
         <freejoint />
         <inertial mass="0.03" diaginertia="5.6e-05 5.6e-05 5.6e-05" pos="0 0 0" />
         <geom type="sphere" size="0.02" material="dust_material" />
      </body>
      <body name="ball_135" pos="0.9823 -0.0308 0.48">
         <freejoint />
         <inertial mass="0.03" diaginertia="5.6e-05 5.6e-05 5.6e-05" pos="0 0 0" />
         <geom type="sphere" size="0.02" material="dust_material" />
      </body>
      <body name="ball_136" pos="-0.9148 0.2163 0.48">
         <freejoint />
         <inertial mass="0.03" diaginertia="5.6e-05 5.6e-05 5.6e-05" pos="0 0 0" />
         <geom type="sphere" size="0.02" material="dust_material" />
      </body>
      <body name="ball_137" pos="0.1973 0.1425 0.48">
         <freejoint />
         <inertial mass="0.03" diaginertia="5.6e-05 5.6e-05 5.6e-05" pos="0 0 0" />
         <geom type="sphere" size="0.02" material="dust_material" />
      </body>
      <body name="ball_138" pos="-0.5555 0.1641 0.48">
         <freejoint />
         <inertial mass="0.03" diaginertia="5.6e-05 5.6e-05 5.6e-05" pos="0 0 0" />
         <geom type="sphere" size="0.02" material="dust_material" />
      </body>
      <body name="ball_139" pos="0.1598 0.0261 0.48">
         <freejoint />
         <inertial mass="0.03" diaginertia="5.6e-05 5.6e-05 5.6e-05" pos="0 0 0" />
         <geom type="sphere" size="0.02" material="dust_material" />
      </body>
      <body name="ball_140" pos="0.9627 0.4876 0.48">
         <freejoint />
         <inertial mass="0.03" diaginertia="5.6e-05 5.6e-05 5.6e-05" pos="0 0 0" />
         <geom type="sphere" size="0.02" material="dust_material" />
      </body>
      <body name="ball_141" pos="0.8073 -0.445 0.48">
         <freejoint />
         <inertial mass="0.03" diaginertia="5.6e-05 5.6e-05 5.6e-05" pos="0 0 0" />
         <geom type="sphere" size="0.02" material="dust_material" />
      </body>
      <body name="ball_142" pos="0.3458 -0.2036 0.48">
         <freejoint />
         <inertial mass="0.03" diaginertia="5.6e-05 5.6e-05 5.6e-05" pos="0 0 0" />
         <geom type="sphere" size="0.02" material="dust_material" />
      </body>
      <body name="ball_143" pos="-0.1865 0.0348 0.48">
         <freejoint />
         <inertial mass="0.03" diaginertia="5.6e-05 5.6e-05 5.6e-05" pos="0 0 0" />
         <geom type="sphere" size="0.02" material="dust_material" />
      </body>
      <body name="ball_144" pos="-0.3886 -0.4805 0.48">
         <freejoint />
         <inertial mass="0.03" diaginertia="5.6e-05 5.6e-05 5.6e-05" pos="0 0 0" />
         <geom type="sphere" size="0.02" material="dust_material" />
      </body>
      <body name="ball_145" pos="0.5187 -0.2045 0.48">
         <freejoint />
         <inertial mass="0.03" diaginertia="5.6e-05 5.6e-05 5.6e-05" pos="0 0 0" />
         <geom type="sphere" size="0.02" material="dust_material" />
      </body>
      <body name="ball_146" pos="-0.0916 0.455 0.48">
         <freejoint />
         <inertial mass="0.03" diaginertia="5.6e-05 5.6e-05 5.6e-05" pos="0 0 0" />
         <geom type="sphere" size="0.02" material="dust_material" />
      </body>
      <body name="ball_147" pos="0.8573 -0.49 0.48">
         <freejoint />
         <inertial mass="0.03" diaginertia="5.6e-05 5.6e-05 5.6e-05" pos="0 0 0" />
         <geom type="sphere" size="0.02" material="dust_material" />
      </body>
      <body name="ball_148" pos="0.4019 -0.4576 0.48">
         <freejoint />
         <inertial mass="0.03" diaginertia="5.6e-05 5.6e-05 5.6e-05" pos="0 0 0" />
         <geom type="sphere" size="0.02" material="dust_material" />
      </body>
      <body name="ball_149" pos="0.495 -0.2624 0.48">
         <freejoint />
         <inertial mass="0.03" diaginertia="5.6e-05 5.6e-05 5.6e-05" pos="0 0 0" />
         <geom type="sphere" size="0.02" material="dust_material" />
      </body>
      <body name="ball_150" pos="0.4715 0.2844 0.48">
         <freejoint />
         <inertial mass="0.03" diaginertia="5.6e-05 5.6e-05 5.6e-05" pos="0 0 0" />
         <geom type="sphere" size="0.02" material="dust_material" />
      </body>
   </worldbody>

   <!-- ================= ACTUATORS ================= -->
   <actuator>
      <position class="position" name="shoulder_pan_act" joint="shoulder_pan" />
      <position class="position" name="shoulder_lift_act" joint="shoulder_lift" />
      <position class="position_limited" name="elbow_act" joint="elbow" />
      <position class="position_small" name="wrist_1_act" joint="wrist_1" />
      <position class="position_small" name="wrist_2_act" joint="wrist_2" />
      <position class="position_small" name="wrist_3_act" joint="wrist_3" />
   </actuator>

</mujoco>